Exception in thread Thread-1:
Traceback (most recent call last):
  File "/usr/lib/python3.10/threading.py", line 1016, in _bootstrap_inner
    self.run()
  File "/srv/bench/frappe-bench/env/lib/python3.10/site-packages/redis/client.py", line 1799, in run
    pubsub.get_message(ignore_subscribe_messages=True, timeout=sleep_time)
  File "/srv/bench/frappe-bench/env/lib/python3.10/site-packages/redis/client.py", line 1690, in get_message
    response = self.parse_response(block=(timeout is None), timeout=timeout)
  File "/srv/bench/frappe-bench/env/lib/python3.10/site-packages/redis/client.py", line 1542, in parse_response
    response = self._execute(conn, try_read)
  File "/srv/bench/frappe-bench/env/lib/python3.10/site-packages/redis/client.py", line 1518, in _execute
    return conn.retry.call_with_retry(
  File "/srv/bench/frappe-bench/env/lib/python3.10/site-packages/redis/retry.py", line 49, in call_with_retry
    fail(error)
  File "/srv/bench/frappe-bench/env/lib/python3.10/site-packages/redis/client.py", line 1520, in <lambda>
    lambda error: self._disconnect_raise_connect(conn, error),
  File "/srv/bench/frappe-bench/env/lib/python3.10/site-packages/redis/client.py", line 1507, in _disconnect_raise_connect
    raise error
  File "/srv/bench/frappe-bench/env/lib/python3.10/site-packages/redis/retry.py", line 46, in call_with_retry
    return do()
  File "/srv/bench/frappe-bench/env/lib/python3.10/site-packages/redis/client.py", line 1519, in <lambda>
    lambda: command(*args, **kwargs),
  File "/srv/bench/frappe-bench/env/lib/python3.10/site-packages/redis/client.py", line 1536, in try_read
    if not conn.can_read(timeout=timeout):
  File "/srv/bench/frappe-bench/env/lib/python3.10/site-packages/redis/connection.py", line 861, in can_read
    return self._parser.can_read(timeout)
  File "/srv/bench/frappe-bench/env/lib/python3.10/site-packages/redis/connection.py", line 444, in can_read
    return self.read_from_socket(timeout=timeout, raise_on_timeout=False)
  File "/srv/bench/frappe-bench/env/lib/python3.10/site-packages/redis/connection.py", line 455, in read_from_socket
    raise ConnectionError(SERVER_CLOSED_CONNECTION_ERROR)
redis.exceptions.ConnectionError: Connection closed by server.
Traceback (most recent call last):
  File "/srv/bench/frappe-bench/env/lib/python3.10/site-packages/redis/connection.py", line 699, in connect
    sock = self.retry.call_with_retry(
  File "/srv/bench/frappe-bench/env/lib/python3.10/site-packages/redis/retry.py", line 46, in call_with_retry
    return do()
  File "/srv/bench/frappe-bench/env/lib/python3.10/site-packages/redis/connection.py", line 700, in <lambda>
    lambda: self._connect(), lambda error: self.disconnect(error)
  File "/srv/bench/frappe-bench/env/lib/python3.10/site-packages/redis/connection.py", line 1002, in _connect
    raise err
  File "/srv/bench/frappe-bench/env/lib/python3.10/site-packages/redis/connection.py", line 990, in _connect
    sock.connect(socket_address)
ConnectionRefusedError: [Errno 111] Connection refused

During handling of the above exception, another exception occurred:

Traceback (most recent call last):
  File "/usr/lib/python3.10/runpy.py", line 196, in _run_module_as_main
    return _run_code(code, main_globals, None,
  File "/usr/lib/python3.10/runpy.py", line 86, in _run_code
    exec(code, run_globals)
  File "/srv/bench/frappe-bench/apps/frappe/frappe/utils/bench_helper.py", line 114, in <module>
    main()
  File "/srv/bench/frappe-bench/apps/frappe/frappe/utils/bench_helper.py", line 20, in main
    click.Group(commands=commands)(prog_name="bench")
  File "/srv/bench/frappe-bench/env/lib/python3.10/site-packages/click/core.py", line 1157, in __call__
    return self.main(*args, **kwargs)
  File "/srv/bench/frappe-bench/env/lib/python3.10/site-packages/click/core.py", line 1078, in main
    rv = self.invoke(ctx)
  File "/srv/bench/frappe-bench/env/lib/python3.10/site-packages/click/core.py", line 1688, in invoke
    return _process_result(sub_ctx.command.invoke(sub_ctx))
  File "/srv/bench/frappe-bench/env/lib/python3.10/site-packages/click/core.py", line 1688, in invoke
    return _process_result(sub_ctx.command.invoke(sub_ctx))
  File "/srv/bench/frappe-bench/env/lib/python3.10/site-packages/click/core.py", line 1434, in invoke
    return ctx.invoke(self.callback, **ctx.params)
  File "/srv/bench/frappe-bench/env/lib/python3.10/site-packages/click/core.py", line 783, in invoke
    return __callback(*args, **kwargs)
  File "/srv/bench/frappe-bench/apps/frappe/frappe/commands/scheduler.py", line 208, in start_worker
    start_worker(
  File "/srv/bench/frappe-bench/apps/frappe/frappe/utils/background_jobs.py", line 335, in start_worker
    worker.work(
  File "/srv/bench/frappe-bench/env/lib/python3.10/site-packages/rq/worker.py", line 456, in work
    self.teardown()
  File "/srv/bench/frappe-bench/env/lib/python3.10/site-packages/rq/worker.py", line 1047, in teardown
    self.unsubscribe()
  File "/srv/bench/frappe-bench/env/lib/python3.10/site-packages/rq/worker.py", line 624, in unsubscribe
    self.pubsub.unsubscribe()
  File "/srv/bench/frappe-bench/env/lib/python3.10/site-packages/redis/client.py", line 1659, in unsubscribe
    return self.execute_command("UNSUBSCRIBE", *args)
  File "/srv/bench/frappe-bench/env/lib/python3.10/site-packages/redis/client.py", line 1479, in execute_command
    self._execute(connection, connection.send_command, *args, **kwargs)
  File "/srv/bench/frappe-bench/env/lib/python3.10/site-packages/redis/client.py", line 1518, in _execute
    return conn.retry.call_with_retry(
  File "/srv/bench/frappe-bench/env/lib/python3.10/site-packages/redis/retry.py", line 49, in call_with_retry
    fail(error)
  File "/srv/bench/frappe-bench/env/lib/python3.10/site-packages/redis/client.py", line 1520, in <lambda>
    lambda error: self._disconnect_raise_connect(conn, error),
  File "/srv/bench/frappe-bench/env/lib/python3.10/site-packages/redis/client.py", line 1507, in _disconnect_raise_connect
    raise error
  File "/srv/bench/frappe-bench/env/lib/python3.10/site-packages/redis/retry.py", line 46, in call_with_retry
    return do()
  File "/srv/bench/frappe-bench/env/lib/python3.10/site-packages/redis/client.py", line 1519, in <lambda>
    lambda: command(*args, **kwargs),
  File "/srv/bench/frappe-bench/env/lib/python3.10/site-packages/redis/connection.py", line 847, in send_command
    self.send_packed_command(
  File "/srv/bench/frappe-bench/env/lib/python3.10/site-packages/redis/connection.py", line 817, in send_packed_command
    self.connect()
  File "/srv/bench/frappe-bench/env/lib/python3.10/site-packages/redis/connection.py", line 705, in connect
    raise ConnectionError(self._error_message(e))
redis.exceptions.ConnectionError: Error 111 connecting to 127.0.0.1:11000. Connection refused.
Exception in thread Thread-1:
Traceback (most recent call last):
  File "/usr/lib/python3.10/threading.py", line 1016, in _bootstrap_inner
    self.run()
  File "/srv/bench/frappe-bench/env/lib/python3.10/site-packages/redis/client.py", line 1799, in run
    pubsub.get_message(ignore_subscribe_messages=True, timeout=sleep_time)
  File "/srv/bench/frappe-bench/env/lib/python3.10/site-packages/redis/client.py", line 1690, in get_message
    response = self.parse_response(block=(timeout is None), timeout=timeout)
  File "/srv/bench/frappe-bench/env/lib/python3.10/site-packages/redis/client.py", line 1542, in parse_response
    response = self._execute(conn, try_read)
  File "/srv/bench/frappe-bench/env/lib/python3.10/site-packages/redis/client.py", line 1518, in _execute
    return conn.retry.call_with_retry(
  File "/srv/bench/frappe-bench/env/lib/python3.10/site-packages/redis/retry.py", line 49, in call_with_retry
    fail(error)
  File "/srv/bench/frappe-bench/env/lib/python3.10/site-packages/redis/client.py", line 1520, in <lambda>
    lambda error: self._disconnect_raise_connect(conn, error),
  File "/srv/bench/frappe-bench/env/lib/python3.10/site-packages/redis/client.py", line 1507, in _disconnect_raise_connect
    raise error
  File "/srv/bench/frappe-bench/env/lib/python3.10/site-packages/redis/retry.py", line 46, in call_with_retry
    return do()
  File "/srv/bench/frappe-bench/env/lib/python3.10/site-packages/redis/client.py", line 1519, in <lambda>
    lambda: command(*args, **kwargs),
  File "/srv/bench/frappe-bench/env/lib/python3.10/site-packages/redis/client.py", line 1536, in try_read
    if not conn.can_read(timeout=timeout):
  File "/srv/bench/frappe-bench/env/lib/python3.10/site-packages/redis/connection.py", line 861, in can_read
    return self._parser.can_read(timeout)
  File "/srv/bench/frappe-bench/env/lib/python3.10/site-packages/redis/connection.py", line 444, in can_read
    return self.read_from_socket(timeout=timeout, raise_on_timeout=False)
  File "/srv/bench/frappe-bench/env/lib/python3.10/site-packages/redis/connection.py", line 455, in read_from_socket
    raise ConnectionError(SERVER_CLOSED_CONNECTION_ERROR)
redis.exceptions.ConnectionError: Connection closed by server.
Traceback (most recent call last):
  File "/srv/bench/frappe-bench/env/lib/python3.10/site-packages/redis/connection.py", line 699, in connect
    sock = self.retry.call_with_retry(
  File "/srv/bench/frappe-bench/env/lib/python3.10/site-packages/redis/retry.py", line 46, in call_with_retry
    return do()
  File "/srv/bench/frappe-bench/env/lib/python3.10/site-packages/redis/connection.py", line 700, in <lambda>
    lambda: self._connect(), lambda error: self.disconnect(error)
  File "/srv/bench/frappe-bench/env/lib/python3.10/site-packages/redis/connection.py", line 1002, in _connect
    raise err
  File "/srv/bench/frappe-bench/env/lib/python3.10/site-packages/redis/connection.py", line 990, in _connect
    sock.connect(socket_address)
ConnectionRefusedError: [Errno 111] Connection refused

During handling of the above exception, another exception occurred:

Traceback (most recent call last):
  File "/usr/lib/python3.10/runpy.py", line 196, in _run_module_as_main
    return _run_code(code, main_globals, None,
  File "/usr/lib/python3.10/runpy.py", line 86, in _run_code
    exec(code, run_globals)
  File "/srv/bench/frappe-bench/apps/frappe/frappe/utils/bench_helper.py", line 114, in <module>
    main()
  File "/srv/bench/frappe-bench/apps/frappe/frappe/utils/bench_helper.py", line 20, in main
    click.Group(commands=commands)(prog_name="bench")
  File "/srv/bench/frappe-bench/env/lib/python3.10/site-packages/click/core.py", line 1157, in __call__
    return self.main(*args, **kwargs)
  File "/srv/bench/frappe-bench/env/lib/python3.10/site-packages/click/core.py", line 1078, in main
    rv = self.invoke(ctx)
  File "/srv/bench/frappe-bench/env/lib/python3.10/site-packages/click/core.py", line 1688, in invoke
    return _process_result(sub_ctx.command.invoke(sub_ctx))
  File "/srv/bench/frappe-bench/env/lib/python3.10/site-packages/click/core.py", line 1688, in invoke
    return _process_result(sub_ctx.command.invoke(sub_ctx))
  File "/srv/bench/frappe-bench/env/lib/python3.10/site-packages/click/core.py", line 1434, in invoke
    return ctx.invoke(self.callback, **ctx.params)
  File "/srv/bench/frappe-bench/env/lib/python3.10/site-packages/click/core.py", line 783, in invoke
    return __callback(*args, **kwargs)
  File "/srv/bench/frappe-bench/apps/frappe/frappe/commands/scheduler.py", line 208, in start_worker
    start_worker(
  File "/srv/bench/frappe-bench/apps/frappe/frappe/utils/background_jobs.py", line 335, in start_worker
    worker.work(
  File "/srv/bench/frappe-bench/env/lib/python3.10/site-packages/rq/worker.py", line 456, in work
    self.teardown()
  File "/srv/bench/frappe-bench/env/lib/python3.10/site-packages/rq/worker.py", line 1047, in teardown
    self.unsubscribe()
  File "/srv/bench/frappe-bench/env/lib/python3.10/site-packages/rq/worker.py", line 624, in unsubscribe
    self.pubsub.unsubscribe()
  File "/srv/bench/frappe-bench/env/lib/python3.10/site-packages/redis/client.py", line 1659, in unsubscribe
    return self.execute_command("UNSUBSCRIBE", *args)
  File "/srv/bench/frappe-bench/env/lib/python3.10/site-packages/redis/client.py", line 1479, in execute_command
    self._execute(connection, connection.send_command, *args, **kwargs)
  File "/srv/bench/frappe-bench/env/lib/python3.10/site-packages/redis/client.py", line 1518, in _execute
    return conn.retry.call_with_retry(
  File "/srv/bench/frappe-bench/env/lib/python3.10/site-packages/redis/retry.py", line 49, in call_with_retry
    fail(error)
  File "/srv/bench/frappe-bench/env/lib/python3.10/site-packages/redis/client.py", line 1520, in <lambda>
    lambda error: self._disconnect_raise_connect(conn, error),
  File "/srv/bench/frappe-bench/env/lib/python3.10/site-packages/redis/client.py", line 1507, in _disconnect_raise_connect
    raise error
  File "/srv/bench/frappe-bench/env/lib/python3.10/site-packages/redis/retry.py", line 46, in call_with_retry
    return do()
  File "/srv/bench/frappe-bench/env/lib/python3.10/site-packages/redis/client.py", line 1519, in <lambda>
    lambda: command(*args, **kwargs),
  File "/srv/bench/frappe-bench/env/lib/python3.10/site-packages/redis/connection.py", line 847, in send_command
    self.send_packed_command(
  File "/srv/bench/frappe-bench/env/lib/python3.10/site-packages/redis/connection.py", line 817, in send_packed_command
    self.connect()
  File "/srv/bench/frappe-bench/env/lib/python3.10/site-packages/redis/connection.py", line 705, in connect
    raise ConnectionError(self._error_message(e))
redis.exceptions.ConnectionError: Error 111 connecting to 127.0.0.1:11000. Connection refused.
2024-01-23 22:51:53,839 [Job 360.armsit.com::a6c4d09a-4f7c-4e92-be07-9497d830e297]: exception raised while executing (frappe.utils.background_jobs.execute_job)
Traceback (most recent call last):
  File "/srv/bench/frappe-bench/env/lib/python3.10/site-packages/rq/worker.py", line 1428, in perform_job
    rv = job.perform()
  File "/srv/bench/frappe-bench/env/lib/python3.10/site-packages/rq/job.py", line 1278, in perform
    self._result = self._execute()
  File "/srv/bench/frappe-bench/env/lib/python3.10/site-packages/rq/job.py", line 1315, in _execute
    result = self.func(*self.args, **self.kwargs)
  File "/srv/bench/frappe-bench/apps/frappe/frappe/utils/background_jobs.py", line 216, in execute_job
    retval = method(**kwargs)
  File "/srv/bench/frappe-bench/apps/frappe/frappe/model/document.py", line 1629, in execute_action
    doc = frappe.get_doc(__doctype, __name)
  File "/srv/bench/frappe-bench/apps/frappe/frappe/__init__.py", line 1265, in get_doc
    doc = frappe.model.document.get_doc(*args, **kwargs)
  File "/srv/bench/frappe-bench/apps/frappe/frappe/model/document.py", line 82, in get_doc
    return controller(*args, **kwargs)
  File "/srv/bench/frappe-bench/apps/frappe/frappe/model/document.py", line 123, in __init__
    self.load_from_db()
  File "/srv/bench/frappe-bench/apps/frappe/frappe/model/document.py", line 169, in load_from_db
    frappe.throw(
  File "/srv/bench/frappe-bench/apps/frappe/frappe/__init__.py", line 578, in throw
    msgprint(
  File "/srv/bench/frappe-bench/apps/frappe/frappe/__init__.py", line 550, in msgprint
    _raise_exception()
  File "/srv/bench/frappe-bench/apps/frappe/frappe/__init__.py", line 501, in _raise_exception
    raise exc
frappe.exceptions.DoesNotExistError: Role Profile HR not found

supervisor: couldn't chdir to /srv/bench/frappe-benchkillasgroup=true: ENOENT
supervisor: child process was not spawned
supervisor: couldn't chdir to /srv/bench/frappe-benchkillasgroup=true: ENOENT
supervisor: child process was not spawned
supervisor: couldn't chdir to /srv/bench/frappe-benchkillasgroup=true: ENOENT
supervisor: child process was not spawned
supervisor: couldn't chdir to /srv/bench/frappe-benchkillasgroup=true: ENOENT
supervisor: child process was not spawned
supervisor: couldn't chdir to /srv/bench/frappe-benchkillasgroup=true: ENOENT
supervisor: child process was not spawned
supervisor: couldn't chdir to /srv/bench/frappe-benchkillasgroup=true: ENOENT
supervisor: child process was not spawned
supervisor: couldn't chdir to /srv/bench/frappe-benchkillasgroup=true: ENOENT
supervisor: child process was not spawned
